I'm sorry, but an uncaught exception occurred.

While running game code:
  File "game/script.rpy", line 188, in script
    $ time_convert(time_lapsed)
  File "game/script.rpy", line 188, in <module>
    $ time_convert(time_lapsed)
  File "game/script.rpy", line 9, in time_convert
    renpy.say(("Time Lapsed = {0}:{1}:{2}".format(int(hours),int(mins),int(sec))))
TypeError: say() takes at least 2 arguments (1 given)

-- Full Traceback ------------------------------------------------------------

Full traceback:
  File "game/script.rpy", line 188, in script
    $ time_convert(time_lapsed)
  File "/Applications/renpy-7.4.11-sdk/renpy/ast.py", line 928, in execute
    renpy.python.py_exec_bytecode(self.code.bytecode, self.hide, store=self.store)
  File "/Applications/renpy-7.4.11-sdk/renpy/python.py", line 2245, in py_exec_bytecode
    exec(bytecode, globals, locals)
  File "game/script.rpy", line 188, in <module>
    $ time_convert(time_lapsed)
  File "game/script.rpy", line 9, in time_convert
    renpy.say(("Time Lapsed = {0}:{1}:{2}".format(int(hours),int(mins),int(sec))))
TypeError: say() takes at least 2 arguments (1 given)

Darwin-21.1.0-x86_64-i386-64bit
Ren'Py 7.4.11.2266
IDP2022 1.0
Fri May 13 12:42:50 2022
